在写代码时，我们要尽可能的考虑==边界问题，性能问题==，还要考虑==各种可能存在的错误和异常==。

随着经验的增加，你会慢慢了解这些异常，并掌握处理异常的方法。

- 什么是异常
- 如何捕获异常
- 主动抛异常
- 如何分析和收集异常



在程序解析阶段，异常不会发生 => 只有遇到特定情况时才会发生错误

一个程序员，在写程序的时候，要考虑很多，基于过往的经验，他会刻意的处理一些边界情况或者特殊情况，以避免发生错误。



## 简介导入

```python
# 没有异常处理
num = int('abc')
print(num)          #报错

# 异常处理
try:
    num = int('abc')      #try里的代码是受保护的
    print(num)
except Exception as e:
    print(e)            #输出invalid literal for int() with base 10: 'abc'，程序正常运行
```

e是由**Exception类 实例化**的一个对象

```python
class Exception(BaseException):
    """ Common base class for all non-exit exceptions. """
    def __init__(self, *args, **kwargs): # real signature unknown
        pass

    @staticmethod # known case of __new__
    def __new__(*args, **kwargs): # real signature unknown
        """ Create and return a new object.  See help(type) for accurate signature. """
        pass
```





## 常见异常分类

Exception是万能的异常捕捉方法，可以捕捉到任何错误。

```python
li = []
inp = input('请输入内容：')
try:
    li = []
    li[999]

except IndexError as e:  # 特殊异常需要优先匹配
    print('索引错误')
except Exception as e:
    print(e)
```

| 常见异常          |                                                              |
| ----------------- | ------------------------------------------------------------ |
| AttributeError    | 试图访问一个对象没有的树形，比如foo.x，但是foo**没有属性x**  |
| IOError           | 输入/输出异常；基本上是无法打开文件                          |
| ImportError       | 无法引入模块或包；基本上是路径问题或名称错误                 |
| IndentationError  | 语法错误（的子类） ；代码没有正确对齐                        |
| IndexError        | 下标索引超出序列边界，比如当x只有三个元素，却试图访问x[5]    |
| KeyError          | 试图访问**字典里不存在的键**                                 |
| KeyboardInterrupt | Ctrl+C被按下                                                 |
| NameError         | 使用一个还未被赋予对象的变量                                 |
| SyntaxError       | Python代码非法，代码不能编译(个人认为这是语法错误，写错了）  |
| TypeError         | '1' + 3                                                      |
| UnboundLocalError | 试图访问一个**还未被设置的局部变量**，基本上是由于另有一个同名的全局变量，导致你以为正在访问它 |
| ValueError        | 传入一个调用者不期望的值，即使值的类型是正确的               |
| ZeroDivisionError | 10 / 0                                                       |

Python的错误其实也是class，==所有的错误类型都继承自BaseException==，所以在使用except时需要注意的是，它不但捕获该类型的错误，还把其子类也“一网打尽”。比如：

```python
try:
    foo()
except ValueError as e:
    print('ValueError')
except UnicodeError as e:
    print('UnicodeError')
```

第二个except永远也捕获不到UnicodeError，因为UnicodeError是ValueError的子类，==如果有，也被第一个except给捕获了==。



### 异常类的继承关系

```python
BaseException
 +-- SystemExit
 +-- KeyboardInterrupt
 +-- GeneratorExit
 +-- Exception
      +-- StopIteration
      +-- StopAsyncIteration
      +-- ArithmeticError
       |     +-- FloatingPointError
       |     +-- OverflowError
       |     +-- ZeroDivisionError
      +-- AssertionError
      +-- AttributeError
      +-- BufferError
      +-- EOFError
      +-- ImportError
           +-- ModuleNotFoundError
      +-- LookupError
       |     +-- IndexError
       |     +-- KeyError
      +-- MemoryError
      +-- NameError
       |     +-- UnboundLocalError
      +-- OSError
       |     +-- BlockingIOError
       |     +-- ChildProcessError
       |     +-- ConnectionError
       |      |     +-- BrokenPipeError
       |      |     +-- ConnectionAbortedError
       |      |     +-- ConnectionRefusedError
       |      |     +-- ConnectionResetError
       |     +-- FileExistsError
       |     +-- FileNotFoundError
       |     +-- InterruptedError
       |     +-- IsADirectoryError
       |     +-- NotADirectoryError
       |     +-- PermissionError
       |     +-- ProcessLookupError
       |     +-- TimeoutError
      +-- ReferenceError
      +-- RuntimeError
       |     +-- NotImplementedError
       |     +-- RecursionError
      +-- SyntaxError
       |     +-- IndentationError
       |          +-- TabError
      +-- SystemError
      +-- TypeError
      +-- ValueError
       |     +-- UnicodeError
       |          +-- UnicodeDecodeError
       |          +-- UnicodeEncodeError
       |          +-- UnicodeTranslateError
      +-- Warning
           +-- DeprecationWarning
           +-- PendingDeprecationWarning
           +-- RuntimeWarning
           +-- SyntaxWarning
           +-- UserWarning
           +-- FutureWarning
           +-- ImportWarning
           +-- UnicodeWarning
           +-- BytesWarning
           +-- ResourceWarning
```



## 实例

```python
#IndexError
dic = ["wupeiqi", 'alex']
try:
    dic[10] #下标越界
except IndexError, e:
    print e

#KeyError
dic = {'k1':'v1'}
try:
    dic['k20']  #不存在的key
except KeyError, e:
    print e
    
#ValueError
s1 = 'hello'
try:
    int(s1) #字符串无法转化为int
except ValueError, e:
    print e
```



使用try...except捕获错误还有一个巨大的好处，就是可以跨越多层调用，比如函数main()调用foo()，foo()调用bar()，结果bar()出错了，这时，**只要main()捕获到了**，就可以处理。

也就是说，不需要在每个可能出错的地方去捕获错误，只要**在合适的层次去捕获错误**就可以了。

这样一来，就大大减少了写try...except...finally的麻烦。

```python
def foo(s):
    return 10 / int(s)

def bar(s):
    return foo(s) * 2

def main():
    try:
        bar('0')
    except Exception as e:
        print('Error:', e)
    finally:
        print('finally...')
```







# 应用|捕获异常 try... except... finally...

一旦发生异常，程序就会终止，这是非常糟糕的事情，这种糟糕体现在两方面

1. 即便发生了异常，==业务上可以忽略它==，那么程序应当继续执行
2. 程序终止，使得异常的==信息没有被保留下来==，不利于问题的分析和总结

为了提高程序的健壮性和解决问题，可以将异常捕获，根据业务要求来做对应的处理

```python
try:
    # 主代码块
    pass
except KeyError as e:
    # 异常时，执行该块
    pass
else:
    # 主代码块执行完，执行该块
    pass
finally:
    # 无论异常与否，最终执行该块
    pass
```





```python
### 当没有异常发生时，就会执行else语句块里的代码
def test(a, b):
    try:
        print(a/b)
    except ZeroDivisionError:
        print('0不能做分母')
    except ValueError:
        print("类型错误")
    else:
        print('什么异常都没发生')

if __name__ == '__main__':
    test(10, 5)
    test(10, 0)
    
    
### 什么异常都不指定，任何异常都会被捕捉
'''这不是一个好的写法
因为这意味着，你根本不了解你的程序，因为不了解，你连可能发生的异常是什么都不清楚，这是很致命的，你不了解你自己写出来的程序，还怎么指望它能正常工作？
'''
def test(a, b):
    try:
        print(a/b)
    except:
        print('发生异常')
```



在finally语句块里做清理操作，因为不论try子句里是否发生异常，也不论你在except语句块里做了什么操作，总之，最终一定会执行finally语句块里的代码，这就保证了这里的代码最后一定会被执行，所以，清理收尾的工作一定会进行。

- 输出日志

```python
def divide(x, y):
    try:
        result = x / y
    except ZeroDivisionError:
        print("division by zero!")
    else:
        print("result is", result)
    finally:
        print("executing finally clause")

if __name__ == '__main__':
    divide(10, 5)
    divide(10, 0)
```







# 应用|主动抛异常 raise

某些情况下，你需要反馈消息给更上层的调用者，告诉它有一些异常情况发生，而你抛出异常的地方，没有能力处理它，因此需要向上抛出异常。

为什么不让系统自己抛出异常呢？

- 一个原因是上层的调用者本身就希望能够捕获有别于系统异常的自定义异常
- 二来，有些情况下，程序的逻辑是没有异常的，但是，从业务角度考虑，的确是一个不寻常的情况，因此需要我们主动抛出异常。

```python
try:
    raise Exception('错误了。。。')
except Exception as e:
    print e
```



```python
def divide(x, y):
    if y == 0:
        raise ZeroDivisionError("0不能做分母")
    return x/y

if __name__ == '__main__':
    divide(10, 5)
    divide(10, 0)
    
    
### 如果你不想指定，那么可以抛出异常Exception， 它是所有异常的父类
def divide(x, y):
    if y == 0:
        raise Exception("0不能做分母")
    return x/y
```



## 自定义异常⭐

引入自定义的异常类，可以让代码更具可读性，同时对异常的划分更加精细，那么在处理异常时也就更加具有针对性

自定义异常继承自Exception，或者那些类本身就继承自Exception

```python
class WupeiqiException(Exception):
 
    def __init__(self, msg):
        self.message = msg
 
    def __str__(self):
        return self.message
 
try:
    raise WupeiqiException('我的异常')
except WupeiqiException,e:
    print e
```



```python
import requests


class HttpCodeException(Exception):
    pass

def get_html(url, headers):
    res = requests.get(url, headers=headers)
    print(res.status_code)
    if res.status_code != 200:	#抛出异常的情况
        raise HttpCodeException

    return res.text

try:
    text = get_html("http://www.coolpython.net", {})
    print(text)
except HttpCodeException:
    print("状态码不是200")
```





## 结构|断言assert：单元测试

```python
# assert 条件
assert 1 == 1   #条件成立程序正常运行
assert 1 == 2   #不成里就会报错，程序就异常
```





# 异常信息分析

![image-20210123101457322](https://cdn.jsdelivr.net/gh/DaiDuncan/PicUploader/img/20210123101457.png)

1 先关注最后一行绿色框内的信息

- 明确地指明了异常的类型和异常的解释信息

2 蓝色框内的内容：是调用堆栈信息

- 详细的记录了程序的执行路径
- 最后一行正是错误发生的位置

既有出错代码的位置，又有错误的类型与解释，如果还是不能找出问题，那么，可以google了，google时将最后一行绿色框里的内容作为搜索词进行搜索，可以找到大量文章。



## 异常信息收集

traceback模块可以准确获得有关异常的信息，这在稍大点的项目里非常有用

- 大一点的项目里，需要记录程序运行的日志：非常非常重要，将有助于你发现系统的问题

```python
import traceback
def divide(x, y):
    try:
        return x/y
    except:
        msg = traceback.format_exc()	#获取有关异常的详细信息：平时程序遇到bug时报出来的那些异常信息
        print(msg)

if __name__ == '__main__':
    #print(divide(10, 5))
    print(divide(10, 0))
```



```python
Traceback (most recent call last):
  File "/Users/kwsy/PycharmProjects/pythonclass/mytest/test.py", line 4, in divide
    return x/y
ZeroDivisionError: division by zero
```

有了这些信息，你就清楚的知道错误发生在哪里，异常的类型是什么，你甚至可以在日志里将==函数的入参==写入到日志中，这样，更加有助于你解决问题。



# 补充|19个常见的python错误和异常

## 语法|忘记添加:

大多数编辑器在你写代码的时候就会用红色的波浪线提示你

```python
if 3 > 4
    print('ok')
```



## 误将 = 当做 ==

写的太着急了，就少打了一个=，得到的自然也是SyntaxError

```python
a = 4
if a = 4:
    print('ok')
```



## 错误的缩进空格数量

将引发错误“IndentationError: unindent does not match any outer indentation level” ，一次缩进是4个空格

```python
if 1==1:
    print('1')
   print('2')
```



## 错误使用range函数

```python
lst = [1, 2, 3]
for i in range(lst):
    print(lst[i])
```

引发了错误“TypeError: 'list' object cannot be interpreted as an integer”

```python
### 正确做法
lst = [1, 2, 3]
for i in range(len(lst)):
    print(lst[i])
```



## 尝试修改字符串的内容

字符串是不可变对象，无法修改字符串里的内容，下面的代码将会引发错误“TypeError: 'str' object does not support item assignment”

```python
s = "i like python"
s[0] = 'I'
print(s[0])
```





## 尝试将非字符串数据与字符串连接

导致错误“TypeError: must be str, not int”

```python
print('I have ' + 3 + " books")
```



## 字符串缺少引号

引发错误“SyntaxError: EOL while scanning string literal”

```python
print('hello world)
```





## 使用未定义的变量

引发错误“NameError: name 'name' is not defined”

```python
sname = "lilei"

print('my name is ' + name)
```





## 调用对象没有的方法

原本是字符串，但进过一些操作后，变成了其他对象，可能是int，或者None，不论变成什么，总是它都不再是字符串，没有了lower方法

报错“AttributeError: 'NoneType' object has no attribute 'lower'”

```python
string = 'PYTHON'
# 经过一些操作后,string变成了None
string = None
print(string.lower())
```





## 访问不存在的索引

引发索引错误“IndexError: list index out of range”

```python
lst = [1, 2, 3]

print(lst[6])
```





## 使用一个不存在的key

通过key来操作字典，如果key不存在，就会引发错误“KeyError”

```python
dic = {
    'name': 'lili',
    'age': 14
}

print(dic['sex'])
```





## 使用保留字做变量

引发错误“SyntaxError”

```python
class = 'python'
print(class)
```



## 使用不存在的内置函数

```python
lst = [1, 2, 3]
print(avg(lst))
```



## 在函数内修改全局不可变对象

```python
a = 10

def func():
    print(a)

func()
```

上述程序正常执行，可以输出10，对代码稍作修改

```python
a = 10

def func():
    print(a)
    a = 20

func()
```

代码就会报错“UnboundLocalError: local variable 'a' referenced before assignment”，为什么会这样呢?a原本是一个全局变量，在第一段代码里可以正常访问，但是第二段代码里尝试对变量a进行修改，一旦有了修改这个动作，==解释器就认为变量a是一个局部变量==，而不在是全局变量

那么在a = 20这条语句之前尝试输出a的内容就会报错因为在执行print(a)时，局部变量a还不存在。



## 修改range的返回值

range函数创建一个整数序列，但这个序列并不是列表，而是一个迭代器，无法使用索引来进行任何操作

否则就会引发错误"TypeError: 'range' object does not support item assignment"

```python
lst = range(10)
lst[0] = 20
print(lst)
```



## 使用 ++ 或 --操作

```python
a = 0
a++		#a += 1
print(a)
```

很多语言都支持 ++ 操作，但很遗憾python并不支持，上面的代码会报错“SyntaxError: invalid syntax”



## 函数调用时参数数量错误

错误内容分别是“TypeError: func() missing 1 required positional argument: 'b'” 

```python
def func(a, b):
    return a + b

print(func(4))
```

“TypeError: func() takes 2 positional arguments but 3 were given”

```python
def func(a, b):
    return a + b

print(func(4, 4, 5))
```





## 缺少安装包

报错“ImportError: No module named requests”



## 文件路径错误

根本不存在a.txt这个文件，那么就会报错“FileNotFoundError: [Errno 2] No such file or directory: 'a.txt'”

```python
f = open('a.txt')
print(f.read())
```



# #参考文献

[[转摘\]cnblogs | python异常处理](https://www.cnblogs.com/whatisfantasy/p/6038360.html)

[官方文档 | 常见的错误类型和继承关系](https://docs.python.org/3/library/exceptions.html#exception-hierarchy)

[Link: 酷python](http://www.coolpython.net/python_primary/exection/catch.html)